<mujoco model="atom01">
  <compiler angle="radian" meshdir="../meshes/" eulerseq="zyx"/>
    <option timestep='0.001' iterations='100' solver='PGS' gravity='0 0 -9.81'>
    <flag frictionloss="enable"/>
    </option>
    <size njmax="500" nconmax="100" />

    <visual>
        <quality shadowsize='4096'/>
        <map znear='0.05'/>
    </visual>

    <default>
        <joint limited='true'/>
        <motor ctrllimited='true'/>
        <geom  condim='4' contype="1" conaffinity="15" solref='0.0012' friction='0.9 0.2 0.2'/>
        <equality solref='0.001 2'/>
        <default class='visualgeom'>
            <geom material='visualgeom' condim='1' contype='0' conaffinity='0'/>
        </default>
        <default class='obstacle'>
            <geom material='obstacle' condim='3' contype='1' conaffinity='15'/>
        </default>

        <default class='waist_joint_param'>
            <joint  damping="0.01" frictionloss="0.01" armature="0.01"/>
        </default>
        <default class='leg_joint_param'>
            <joint  damping="0.01" frictionloss="0.01" armature="0.01"/>
        </default>
        <default class='arm_joint_param'>
            <joint  damping="0.01" frictionloss="0.01" armature="0.01"/>
        </default>  
    </default>

  <asset>
    <texture type="skybox" builtin="gradient" rgb1="0.3 0.5 0.7" rgb2="0 0 0" width="512" height="512"/>
    <texture name="texplane" type="2d" builtin="checker" rgb1=".2 .3 .4" rgb2=".1 0.15 0.2"
        width="512" height="512" mark="cross" markrgb=".8 .8 .8"/>
    <texture name="texplane2" type="2d" builtin="checker" rgb1="1 0.3137 0.1843" rgb2="0.0 0.30196 0.38039"
        width="512" height="512" mark="cross" markrgb=".8 .8 .8"/>

    <material name="matplane" reflectance="0." texture="texplane" texrepeat="1 1" texuniform="true"/>
    <material name="matplane2" reflectance="0.1" texture="texplane2" texrepeat="1 1" texuniform="true"/>

    <material name='obstacle'  rgba='0.9 0.6 0.2 1'/>
    <material name='visualgeom'  rgba='0.5 0.9 0.2 1'/>

    <mesh name="base_link"  file="../meshes/base_link.STL"/>
    <mesh name="left_thigh_yaw_link"  file="../meshes/left_thigh_yaw_link.STL"/>
    <mesh name="left_thigh_roll_link"  file="../meshes/left_thigh_roll_link.STL"/>
    <mesh name="left_thigh_pitch_link"  file="../meshes/left_thigh_pitch_link.STL"/>
    <mesh name="left_knee_link"  file="../meshes/left_knee_link.STL"/>
    <mesh name="left_ankle_pitch_link"  file="../meshes/left_ankle_pitch_link.STL"/>
    <mesh name="left_ankle_roll_link"  file="../meshes/left_ankle_roll_link.STL"/>
    <mesh name="right_thigh_yaw_link"  file="../meshes/right_thigh_yaw_link.STL"/>
    <mesh name="right_thigh_roll_link"  file="../meshes/right_thigh_roll_link.STL"/>
    <mesh name="right_thigh_pitch_link"  file="../meshes/right_thigh_pitch_link.STL"/>
    <mesh name="right_knee_link"  file="../meshes/right_knee_link.STL"/>
    <mesh name="right_ankle_pitch_link"  file="../meshes/right_ankle_pitch_link.STL"/>
    <mesh name="right_ankle_roll_link"  file="../meshes/right_ankle_roll_link.STL"/>
    <mesh name="torso_link"  file="../meshes/torso_link.STL"/>
    <mesh name="left_arm_pitch_link"  file="../meshes/left_arm_pitch_link.STL"/>
    <mesh name="left_arm_roll_link"  file="../meshes/left_arm_roll_link.STL"/>
    <mesh name="left_arm_yaw_link"  file="../meshes/left_arm_yaw_link.STL"/>
    <mesh name="left_elbow_pitch_link"  file="../meshes/left_elbow_pitch_link.STL"/>
    <mesh name="left_elbow_yaw_link"  file="../meshes/left_elbow_yaw_link.STL"/>
    <mesh name="right_arm_pitch_link"  file="../meshes/right_arm_pitch_link.STL"/>
    <mesh name="right_arm_roll_link"  file="../meshes/right_arm_roll_link.STL"/>
    <mesh name="right_arm_yaw_link"  file="../meshes/right_arm_yaw_link.STL"/>
    <mesh name="right_elbow_pitch_link"  file="../meshes/right_elbow_pitch_link.STL"/>
    <mesh name="right_elbow_yaw_link"  file="../meshes/right_elbow_yaw_link.STL"/>

    <hfield name='hf0' nrow='200' ncol='200' size="10 5 0.2 .1"/>
  </asset>
  
  <worldbody>
    <light directional="true" diffuse=".4 .4 .4" specular="0.1 0.1 0.1" pos="0 0 5.0" dir="0 0 -1" castshadow="false"/>
    <light directional="true" diffuse=".6 .6 .6" specular="0.2 0.2 0.2" pos="0 0 4" dir="0 0 -1"/>
    <geom name="ground" type="plane" size="0 0 1" pos="0.001 0 0" quat="1 0 0 0" material="matplane" condim="1" conaffinity='15'/>

    <body name="base_link" pos="0 0 0.75">
      <site name='imu' size='0.01' pos='0.0 0 0.0'/>
      <inertial pos="-0.077749 -0.00027844 0.03283" quat="-0.00169048 0.848368 0.0018474 0.5294" mass="5.18129" diaginertia="0.0635131 0.0520745 0.0274799"/>
      <joint type='slide' axis='1 0 0' limited='false' />
      <joint type='slide' axis='0 1 0' limited='false' />
      <joint type='slide' axis='0 0 1' limited='false' />
      <joint type='ball' limited='false' />
      <geom type="mesh" rgba="0.75294 0.75294 0.75294 1" mesh="base_link"/>
    <body name="left_thigh_yaw_link" pos="-0.071093 0.0725 -0.051778">
      <inertial pos="-0.0347532 -0.00011232 -0.0572889" quat="0.963282 -0.00103607 0.268489 -0.000464077" mass="1.70246" diaginertia="0.00963073 0.00903649 0.000999141"/>
      <joint name="left_thigh_yaw_joint" pos="0 0 0" axis="-0.499998 0 -0.866027" range="-1 0.2" actuatorfrcrange="-80 80"/>
      <geom type="mesh" rgba="0.69804 0.69804 0.69804 1" mesh="left_thigh_yaw_link" class="visualgeom"/>
      <body name="left_thigh_roll_link" pos="-0.017693 0 -0.072346">
        <inertial pos="0.0556221 -0.00172039 -0.0318405" quat="0.609853 0.345319 0.364323 0.613273" mass="1.71073" diaginertia="0.00911725 0.00854718 0.00101484"/>
        <joint name="left_thigh_roll_joint" pos="0 0 0" axis="0.866027 0 -0.499998" range="-0.2 1" actuatorfrcrange="-80 80"/>
        <geom type="mesh" rgba="0.69804 0.69804 0.69804 1" mesh="left_thigh_roll_link" class="visualgeom"/>
        <body name="left_thigh_pitch_link" pos="0.060622 0.02085 -0.035">
          <inertial pos="0.00015459 -0.0159486 -0.198455" quat="0.708424 -0.0290913 0.0296039 0.704566" mass="2.3468" diaginertia="0.11308 0.111978 0.0016654"/>
          <joint name="left_thigh_pitch_joint" pos="0 0 0" axis="0 1 0" range="-1 1" actuatorfrcrange="-80 80"/>
          <geom type="mesh" rgba="0.69804 0.69804 0.69804 1" mesh="left_thigh_pitch_link" class="visualgeom"/>
          <body name="left_knee_link" pos="0 0 -0.25">
            <inertial pos="-0.00032236 -0.0119319 -0.14554" quat="0.999226 -0.0355387 -1.80997e-05 -0.0168363" mass="1.79037" diaginertia="0.0503904 0.0501174 0.00121675"/>
            <joint name="left_knee_joint" pos="0 0 0" axis="0 1 0" range="-0.2 2.5" actuatorfrcrange="-80 80"/>
            <geom type="mesh" rgba="0.69804 0.69804 0.69804 1" mesh="left_knee_link" class="visualgeom"/>
            <body name="left_ankle_pitch_link" pos="0 -0.02085 -0.3">
              <inertial pos="0 0 0" quat="0.5 0.5 -0.5 0.5" mass="0.084" diaginertia="1.448e-05 8.63e-06 8.63e-06"/>
              <joint name="left_ankle_pitch_joint" pos="0 0 0" axis="0 1 0" range="-0.6 0.6" actuatorfrcrange="-18 18"/>
              <geom type="mesh" rgba="0.69804 0.69804 0.69804 1" mesh="left_ankle_pitch_link" class="visualgeom"/>
              <body name="left_ankle_roll_link">
                <inertial pos="0.015214 0.00220247 -0.0296054" quat="0.382543 0.587316 0.616412 0.358828" mass="0.32034" diaginertia="0.000892889 0.000740895 0.000315957"/>
                <joint name="left_ankle_roll_joint" pos="0 0 0" axis="1 0 0" range="-0.5 0.5" actuatorfrcrange="-18 18"/>
                <geom type="mesh" rgba="0.898039 0.917647 0.929412 1" mesh="left_ankle_roll_link"/>
                </body>
              </body>
            </body>
          </body>
        </body>
      </body>
    <body name="right_thigh_yaw_link" pos="-0.071093 -0.0725 -0.051778">
      <inertial pos="-0.0348474 -0.00011554 -0.0571181" quat="0.962814 -0.000819706 0.270164 0.000481783" mass="1.68566" diaginertia="0.0094851 0.00890807 0.000964316"/>
      <joint name="right_thigh_yaw_joint" pos="0 0 0" axis="-0.499998 0 -0.866027" range="-0.2 1" actuatorfrcrange="-80 80"/>
      <geom type="mesh" rgba="0.752941 0.752941 0.752941 1" mesh="right_thigh_yaw_link" class="visualgeom"/>
      <body name="right_thigh_roll_link" pos="-0.0189924 0 -0.0715958">
        <inertial pos="0.0568073 0.00172039 -0.0327877" quat="0.610283 0.344505 0.362811 0.614198" mass="1.71073" diaginertia="0.00945002 0.00887982 0.00101497"/>
        <joint name="right_thigh_roll_joint" pos="0 0 0" axis="0.866027 0 -0.499998" range="-1 0.2" actuatorfrcrange="-80 80"/>
        <geom type="mesh" rgba="0.752941 0.752941 0.752941 1" mesh="right_thigh_roll_link" class="visualgeom"/>
        <body name="right_thigh_pitch_link" pos="0.0619208 -0.02085 -0.03575">
          <inertial pos="-1.184e-05 0.0159486 -0.198455" quat="0.704887 -0.029259 0.0294343 0.708105" mass="2.3468" diaginertia="0.11308 0.111978 0.00166549"/>
          <joint name="right_thigh_pitch_joint" pos="0 0 0" axis="0 1 0" range="-1 1" actuatorfrcrange="-80 80"/>
          <geom type="mesh" rgba="0.752941 0.752941 0.752941 1" mesh="right_thigh_pitch_link" class="visualgeom"/>
          <body name="right_knee_link" pos="0 0 -0.25">
            <inertial pos="0.00034876 0.0119319 -0.145503" quat="0.999241 -0.0355546 8.98489e-05 -0.0158908" mass="1.79037" diaginertia="0.0503698 0.050097 0.00121663"/>
            <joint name="right_knee_joint" pos="0 0 0" axis="0 1 0" range="-0.2 2.5" actuatorfrcrange="-80 80"/>
            <geom type="mesh" rgba="0.752941 0.752941 0.752941 1" mesh="right_knee_link" class="visualgeom"/>
            <body name="right_ankle_pitch_link" pos="0 0.02085 -0.3">
              <inertial pos="0 0 0" quat="0.5 0.5 -0.5 0.5" mass="0.084" diaginertia="1.448e-05 8.63e-06 8.63e-06"/>
              <joint name="right_ankle_pitch_joint" pos="0 0 0" axis="0 1 0" range="-0.6 0.6" actuatorfrcrange="-18 18"/>
              <geom type="mesh" rgba="0.752941 0.752941 0.752941 1" mesh="right_ankle_pitch_link" class="visualgeom"/>
              <body name="right_ankle_roll_link">
                <inertial pos="0.015214 -0.00220269 -0.0296054" quat="0.616412 0.358828 0.382543 0.587316" mass="0.32034" diaginertia="0.000892889 0.000740895 0.000315957"/>
                <joint name="right_ankle_roll_joint" pos="0 0 0" axis="1 0 0" range="-0.5 0.5" actuatorfrcrange="-18 18"/>
                <geom type="mesh" rgba="0.898039 0.917647 0.929412 1" mesh="right_ankle_roll_link"/>
              </body>
            </body>
          </body>
        </body>
      </body>
    </body>
    <body name="torso_link" pos="-0.0281649 0 0.0672">
      <inertial pos="-0.00231194 -9.24e-05 0.0961963" quat="0.999809 -0.000699376 0.0194543 -0.00149414" mass="7.65615" diaginertia="0.141651 0.128902 0.0396824"/>
      <joint name="torso_joint" pos="0 0 0" axis="0 0 1" range="-3.14 3.14" actuatorfrcrange="-80 80"/>
      <geom type="mesh" rgba="0.752941 0.752941 0.752941 1" mesh="torso_link" class="visualgeom"/>
      <body name="left_arm_pitch_link" pos="0 0.12175 0.206176">
        <inertial pos="-0.00309185 0.0495522 0.00013831" quat="0.507967 0.472609 -0.527069 0.490723" mass="0.48107" diaginertia="0.00142022 0.0013915 0.000117065"/>
        <joint name="left_arm_pitch_joint" pos="0 0 0" axis="0 1 0" range="-1.57 1.57" actuatorfrcrange="-18 18"/>
        <geom type="mesh" rgba="0.752941 0.752941 0.752941 1" mesh="left_arm_pitch_link" class="visualgeom"/>
        <body name="left_arm_roll_link" pos="0.02 0.056 0">
          <inertial pos="-0.00460348 0 -0.0234675" quat="0.695398 0.128147 0.128147 0.695398" mass="0.105691" diaginertia="0.00013391 0.000130532 2.40278e-05"/>
          <joint name="left_arm_roll_joint" pos="0 0 0" axis="1 0 0" range="-0.25 1" actuatorfrcrange="-18 18"/>
          <geom type="mesh" rgba="0.752941 0.752941 0.752941 1" mesh="left_arm_roll_link" class="visualgeom"/>
          <body name="left_arm_yaw_link" pos="-0.02 0 -0.05">
            <inertial pos="-7.689e-05 -0.00130242 -0.105785" quat="0.999969 -0.0076057 0.00027687 -0.00216122" mass="1.1503" diaginertia="0.0192421 0.0192116 0.000399052"/>
            <joint name="left_arm_yaw_joint" pos="0 0 0" axis="0 0 -1" range="-1.57 1.57" actuatorfrcrange="-18 18"/>
            <geom type="mesh" rgba="0.752941 0.752941 0.752941 1" mesh="left_arm_yaw_link" class="visualgeom"/>
            <body name="left_elbow_pitch_link" pos="0 0.02 -0.18875">
              <inertial pos="0.0241777 -0.00451573 0.00015985" quat="-0.118064 0.689884 0.143806 0.699601" mass="0.103246" diaginertia="0.00012912 0.000125773 2.37476e-05"/>
              <joint name="left_elbow_pitch_joint" pos="0 0 0" axis="0 1 0" range="-0.6 1.57" actuatorfrcrange="-18 18"/>
              <geom type="mesh" rgba="0.752941 0.752941 0.752941 1" mesh="left_elbow_pitch_link" class="visualgeom"/>
              <body name="left_elbow_yaw_link" pos="0.05 -0.02 0">
                <inertial pos="0.0525576 -4.832e-05 3.217e-05" quat="-0.0835285 0.702147 -0.0829786 0.70223" mass="0.679567" diaginertia="0.0032618 0.00326022 0.000280868"/>
                <joint name="left_elbow_yaw_joint" pos="0 0 0" axis="1 0 0" range="-1.57 1.57" actuatorfrcrange="-18 18"/>
                <geom type="mesh" rgba="0.752941 0.752941 0.752941 1" mesh="left_elbow_yaw_link" class="visualgeom"/>
              </body>
            </body>
          </body>
        </body>
      </body>
      <body name="right_arm_pitch_link" pos="0 -0.12175 0.206176">
        <inertial pos="-0.00309185 -0.0495522 0.00013829" quat="0.507976 0.472626 -0.527061 0.490706" mass="0.48107" diaginertia="0.00142022 0.0013915 0.000117065"/>
        <joint name="right_arm_pitch_joint" pos="0 0 0" axis="0 1 0" range="-1.57 1.57" actuatorfrcrange="-18 18"/>
        <geom type="mesh" rgba="0.752941 0.752941 0.752941 1" mesh="right_arm_pitch_link" class="visualgeom"/>
        <body name="right_arm_roll_link" pos="0.02 -0.056 0">
          <inertial pos="-0.00423887 -0.0003197 -0.0229993" quat="0.684312 0.123635 0.130321 0.706717" mass="0.103246" diaginertia="0.000128327 0.000124509 2.35146e-05"/>
          <joint name="right_arm_roll_joint" pos="0 0 0" axis="1 0 0" range="-1 0.25" actuatorfrcrange="-18 18"/>
          <geom type="mesh" rgba="0.752941 0.752941 0.752941 1" mesh="right_arm_roll_link" class="visualgeom"/>
          <body name="right_arm_yaw_link" pos="-0.02 0 -0.05">
            <inertial pos="-5.647e-05 0.00129475 -0.105873" quat="0.999901 -0.0076241 0.000177648 -0.0117913" mass="1.14936" diaginertia="0.0192426 0.0192105 0.000398444"/>
            <joint name="right_arm_yaw_joint" pos="0 0 0" axis="0 0 -1" range="-1.57 1.57" actuatorfrcrange="-18 18"/>
            <geom type="mesh" rgba="0.752941 0.752941 0.752941 1" mesh="right_arm_yaw_link" class="visualgeom"/>
            <body name="right_elbow_pitch_link" pos="0 -0.02 -0.18875">
              <inertial pos="0.0234675 0.00460348 0" quat="-0.128147 0.695398 0.128147 0.695398" mass="0.105691" diaginertia="0.00013391 0.000130532 2.40278e-05"/>
              <joint name="right_elbow_pitch_joint" pos="0 0 0" axis="0 1 0" range="-0.6 1.57" actuatorfrcrange="-18 18"/>
              <geom type="mesh" rgba="0.752941 0.752941 0.752941 1" mesh="right_elbow_pitch_link" class="visualgeom"/>
              <body name="right_elbow_yaw_link" pos="0.05 0.02 0">
                <inertial pos="0.0524087 7.821e-05 1.993e-05" quat="-0.146454 0.69182 -0.145905 0.691844" mass="0.681457" diaginertia="0.00326245 0.0032608 0.000282048"/>
                <joint name="right_elbow_yaw_joint" pos="0 0 0" axis="1 0 0" range="-1.57 1.57" actuatorfrcrange="-18 18"/>
                <geom type="mesh" rgba="0.752941 0.752941 0.752941 1" mesh="right_elbow_yaw_link" class="visualgeom"/>
              </body>
            </body>
          </body>
        </body>
      </body>
    </body>
  </body>
  </worldbody>

  <actuator>
    <!-- 腿部关节 -->
    <motor name="left_thigh_yaw" joint="left_thigh_yaw_joint" gear="1" ctrllimited="true" ctrlrange="-200 200"/>
    <motor name="left_thigh_roll" joint="left_thigh_roll_joint" gear="1" ctrllimited="true" ctrlrange="-200 200"/>
    <motor name="left_thigh_pitch" joint="left_thigh_pitch_joint" gear="1" ctrllimited="true" ctrlrange="-200 200"/>
    <motor name="left_knee" joint="left_knee_joint" gear="1" ctrllimited="true" ctrlrange="-200 200"/>
    <motor name="left_ankle_pitch" joint="left_ankle_pitch_joint" gear="1" ctrllimited="true" ctrlrange="-200 200"/>
    <motor name="left_ankle_roll" joint="left_ankle_roll_joint" gear="1" ctrllimited="true" ctrlrange="-200 200"/>

    <motor name="right_thigh_yaw" joint="right_thigh_yaw_joint" gear="1" ctrllimited="true" ctrlrange="-200 200"/>
    <motor name="right_thigh_roll" joint="right_thigh_roll_joint" gear="1" ctrllimited="true" ctrlrange="-200 200"/>
    <motor name="right_thigh_pitch" joint="right_thigh_pitch_joint" gear="1" ctrllimited="true" ctrlrange="-200 200"/>
    <motor name="right_knee" joint="right_knee_joint" gear="1" ctrllimited="true" ctrlrange="-200 200"/>
    <motor name="right_ankle_pitch" joint="right_ankle_pitch_joint" gear="1" ctrllimited="true" ctrlrange="-200 200"/>
    <motor name="right_ankle_roll" joint="right_ankle_roll_joint" gear="1" ctrllimited="true" ctrlrange="-200 200"/>

    <!-- 躯干关节 -->
    <motor name="torso_yaw" joint="torso_joint" gear="1" ctrllimited="true" ctrlrange="-200 200"/>

    <!-- 手臂关节 -->
    <motor name="left_arm_pitch" joint="left_arm_pitch_joint" gear="1" ctrllimited="true" ctrlrange="-200 200"/>
    <motor name="left_arm_roll" joint="left_arm_roll_joint" gear="1" ctrllimited="true" ctrlrange="-200 200"/>
    <motor name="left_arm_yaw" joint="left_arm_yaw_joint" gear="1" ctrllimited="true" ctrlrange="-200 200"/>
    <motor name="left_elbow_pitch" joint="left_elbow_pitch_joint" gear="1" ctrllimited="true" ctrlrange="-200 200"/>
    <motor name="left_elbow_yaw" joint="left_elbow_yaw_joint" gear="1" ctrllimited="true" ctrlrange="-200 200"/>

    <motor name="right_arm_pitch" joint="right_arm_pitch_joint" gear="1" ctrllimited="true" ctrlrange="-200 200"/>
    <motor name="right_arm_roll" joint="right_arm_roll_joint" gear="1" ctrllimited="true" ctrlrange="-200 200"/>
    <motor name="right_arm_yaw" joint="right_arm_yaw_joint" gear="1" ctrllimited="true" ctrlrange="-200 200"/>
    <motor name="right_elbow_pitch" joint="right_elbow_pitch_joint" gear="1" ctrllimited="true" ctrlrange="-200 200"/>
    <motor name="right_elbow_yaw" joint="right_elbow_yaw_joint" gear="1" ctrllimited="true" ctrlrange="-200 200"/>
  </actuator>

     <sensor>
        <actuatorpos name='left_thigh_yaw_p'  actuator='left_thigh_yaw' user='13'/>
        <actuatorpos name='left_thigh_roll_p'  actuator='left_thigh_roll' user='13'/>
        <actuatorpos name='left_thigh_pitch_p'  actuator='left_thigh_pitch' user='13'/>
        <actuatorpos name='left_knee_p'  actuator='left_knee' user='13'/>
        <actuatorpos name='left_ankle_pitch_p'  actuator='left_ankle_pitch' user='13'/>
        <actuatorpos name='left_ankle_roll_p'  actuator='left_ankle_roll' user='13'/>
        <actuatorpos name='right_thigh_yaw_p'  actuator='right_thigh_yaw' user='13'/>
        <actuatorpos name='right_thigh_roll_p'  actuator='right_thigh_roll' user='13'/>
        <actuatorpos name='right_thigh_pitch_p'  actuator='right_thigh_pitch' user='13'/>
        <actuatorpos name='right_knee_p'  actuator='right_knee' user='13'/>
        <actuatorpos name='right_ankle_pitch_p'  actuator='right_ankle_pitch' user='13'/>
        <actuatorpos name='right_ankle_roll_p'  actuator='right_ankle_roll' user='13'/>
        <actuatorpos name='torso_yaw_p'  actuator='torso_yaw' user='13'/>
        <actuatorpos name='left_arm_pitch_p'  actuator='left_arm_pitch' user='13'/>
        <actuatorpos name='left_arm_roll_p'  actuator='left_arm_roll' user='13'/>
        <actuatorpos name='left_arm_yaw_p'  actuator='left_arm_yaw' user='13'/>
        <actuatorpos name='left_elbow_pitch_p'  actuator='left_elbow_pitch' user='13'/>
        <actuatorpos name='left_elbow_yaw_p'  actuator='left_elbow_yaw' user='13'/>
        <actuatorpos name='right_arm_pitch_p'  actuator='right_arm_pitch' user='13'/>
        <actuatorpos name='right_arm_roll_p'  actuator='right_arm_roll' user='13'/>
        <actuatorpos name='right_arm_yaw_p'  actuator='right_arm_yaw' user='13'/>
        <actuatorpos name='right_elbow_pitch_p'  actuator='right_elbow_pitch' user='13'/>
        <actuatorpos name='right_elbow_yaw_p'  actuator='right_elbow_yaw' user='13'/>

        <actuatorvel name='left_thigh_yaw_v'  actuator='left_thigh_yaw' user='13'/>
        <actuatorvel name='left_thigh_roll_v'  actuator='left_thigh_roll' user='13'/>
        <actuatorvel name='left_thigh_pitch_v'  actuator='left_thigh_pitch' user='13'/>
        <actuatorvel name='left_knee_v'  actuator='left_knee' user='13'/>
        <actuatorvel name='left_ankle_pitch_v'  actuator='left_ankle_pitch' user='13'/>
        <actuatorvel name='left_ankle_roll_v'  actuator='left_ankle_roll' user='13'/>
        <actuatorvel name='right_thigh_yaw_v'  actuator='right_thigh_yaw' user='13'/>
        <actuatorvel name='right_thigh_roll_v'  actuator='right_thigh_roll' user='13'/>
        <actuatorvel name='right_thigh_pitch_v'  actuator='right_thigh_pitch' user='13'/>
        <actuatorvel name='right_knee_v'  actuator='right_knee' user='13'/>
        <actuatorvel name='right_ankle_pitch_v'  actuator='right_ankle_pitch' user='13'/>
        <actuatorvel name='right_ankle_roll_v'  actuator='right_ankle_roll' user='13'/>
        <actuatorvel name='torso_yaw_v'  actuator='torso_yaw' user='13'/>
        <actuatorvel name='left_arm_pitch_v'  actuator='left_arm_pitch' user='13'/>
        <actuatorvel name='left_arm_roll_v'  actuator='left_arm_roll' user='13'/>
        <actuatorvel name='left_arm_yaw_v'  actuator='left_arm_yaw' user='13'/>
        <actuatorvel name='left_elbow_pitch_v'  actuator='left_elbow_pitch' user='13'/>
        <actuatorvel name='left_elbow_yaw_v'  actuator='left_elbow_yaw' user='13'/>
        <actuatorvel name='right_arm_pitch_v'  actuator='right_arm_pitch' user='13'/>
        <actuatorvel name='right_arm_roll_v'  actuator='right_arm_roll' user='13'/>
        <actuatorvel name='right_arm_yaw_v'  actuator='right_arm_yaw' user='13'/>
        <actuatorvel name='right_elbow_pitch_v'  actuator='right_elbow_pitch' user='13'/>
        <actuatorvel name='right_elbow_yaw_v'  actuator='right_elbow_yaw' user='13'/>

        <actuatorfrc name='left_thigh_yaw_f'  actuator='left_thigh_yaw' user='13' noise='1e-3'/>
        <actuatorfrc name='left_thigh_roll_f'  actuator='left_thigh_roll' user='13' noise='1e-3'/>
        <actuatorfrc name='left_thigh_pitch_f'  actuator='left_thigh_pitch' user='13' noise='1e-3'/>
        <actuatorfrc name='left_knee_f'  actuator='left_knee' user='13' noise='1e-3'/>
        <actuatorfrc name='left_ankle_pitch_f'  actuator='left_ankle_pitch' user='13' noise='1e-3'/>
        <actuatorfrc name='left_ankle_roll_f'  actuator='left_ankle_roll' user='13' noise='1e-3'/>
        <actuatorfrc name='right_thigh_yaw_f'  actuator='right_thigh_yaw' user='13' noise='1e-3'/>
        <actuatorfrc name='right_thigh_roll_f'  actuator='right_thigh_roll' user='13' noise='1e-3'/>
        <actuatorfrc name='right_thigh_pitch_f'  actuator='right_thigh_pitch' user='13' noise='1e-3'/>
        <actuatorfrc name='right_knee_f'  actuator='right_knee' user='13' noise='1e-3'/>
        <actuatorfrc name='right_ankle_pitch_f'  actuator='right_ankle_pitch' user='13' noise='1e-3'/>
        <actuatorfrc name='right_ankle_roll_f'  actuator='right_ankle_roll' user='13' noise='1e-3'/>
        <actuatorfrc name='torso_yaw_f'  actuator='torso_yaw' user='13' noise='1e-3'/>
        <actuatorfrc name='left_arm_pitch_f'  actuator='left_arm_pitch' user='13' noise='1e-3'/>
        <actuatorfrc name='left_arm_roll_f'  actuator='left_arm_roll' user='13' noise='1e-3'/>
        <actuatorfrc name='left_arm_yaw_f'  actuator='left_arm_yaw' user='13' noise='1e-3'/>
        <actuatorfrc name='left_elbow_pitch_f'  actuator='left_elbow_pitch' user='13' noise='1e-3'/>
        <actuatorfrc name='left_elbow_yaw_f'  actuator='left_elbow_yaw' user='13' noise='1e-3'/>
        <actuatorfrc name='right_arm_pitch_f'  actuator='right_arm_pitch' user='13' noise='1e-3'/>
        <actuatorfrc name='right_arm_roll_f'  actuator='right_arm_roll' user='13' noise='1e-3'/>
        <actuatorfrc name='right_arm_yaw_f'  actuator='right_arm_yaw' user='13' noise='1e-3'/>
        <actuatorfrc name='right_elbow_pitch_f'  actuator='right_elbow_pitch' user='13' noise='1e-3'/>
        <actuatorfrc name='right_elbow_yaw_f'  actuator='right_elbow_yaw' user='13' noise='1e-3'/>


        <framequat     name='orientation' objtype='site' noise='0.001' objname='imu'/>
        <framepos     name='position' objtype='site' noise='0.001' objname='imu'/>
        <gyro          name='angular-velocity'    site='imu' noise='0.005' cutoff='34.9'/>
        <velocimeter   name='linear-velocity'     site='imu' noise='0.001' cutoff='30'/>
        <accelerometer name='linear-acceleration' site='imu' noise='0.005' cutoff='157'/>
        <magnetometer  name='magnetometer'        site='imu'/>

    </sensor>
    <visual>
        <global offwidth="1920" offheight="1080"/>
    </visual>
</mujoco>
